<?xml version="1.0" ?>
<!-- =================================================================================== -->
<!-- |    This document was autogenerated by xacro from /home/chenxunman/4/src/allegro_hand_description/allegro_hand_description_right_tra.xacro | -->
<!-- |    EDITING THIS FILE BY HAND IS NOT RECOMMENDED                                 | -->
<!-- =================================================================================== -->
<robot name="allegro_hand_right" xmlns:xacro="http://ros.org/wiki/xacro">
  <!-- ======================== BASE PARAMS ========================= -->
  <!-- ======================== FINGER PARAMS ======================== -->
  <!-- full height from joint to tip. when used,
         the radius of the finger tip sphere will be subtracted
         and one fixed link will be added for the tip. -->
  <!-- ========================= THUMB PARAMS ========================= -->
  <!-- ========================= LIMITS ========================= -->
  <!-- ============================================================================= -->

    <link name="virtuallink" />
    <gazebo reference="virtuallink">
        <material>Gazebo/Gray</material>
    </gazebo>
    <joint name="virtualjoint" type="fixed">
        <origin xyz="0.0 0.0 0.0" rpy="0 0 0" />
        <parent link="virtuallink" />
        <child link="base_link" />
    </joint>
    <link name="base_link">
        <visual>
			    <origin xyz=" 0 0 0.02"  rpy="0 0 0"/>
			    <geometry>
				      <box size="1 1 0.02" />
			    </geometry>
			    <material name="Black" />
        </visual>
        <collision>
            <origin xyz=" 0 0 0.02"  rpy="0 0 0"/>
            <geometry>
                <box size="1.0 1.0 0.02" />
            </geometry>
        </collision>
        <box_inertial_matrix m="1000" w="1" h="0.02" d="1"/>
    </link>
    <joint name="base_stand_joint" type="fixed">
        <origin xyz="0.0 0.0 0.15" rpy="0 0 0" />        
        <parent link="base_link"/>
        <child link="palm_link" />
    </joint>


  <!-- PALM -->
  <link name="palm_link">
    <visual>
      <geometry>
        <mesh filename="package://allegro_hand_description/meshes/base_link.STL"/>
      </geometry>
       <origin rpy="0.0 0.0 0.0" xyz="0.0 0.0 0 "/>
      <material name="black">
        <color rgba="0.2 0.2 0.2 1"/>
      </material>
    </visual>
    <collision>
      <origin rpy="0.0 0.0 0.0" xyz="-0.009300 0.0 -0.0475"/>
      <geometry>
        <box size="0.0408 0.1130 0.095"/>
      </geometry>
    </collision>
    <inertial>
       <origin rpy="0.0 0.0 0.0" xyz="0.0 0.0 0.0475"/>
      <mass value="0.4154"/>
      <inertia ixx="1e-4" ixy="1e-4" ixz="1e-4" iyy="1e-4" iyz="1e-4" izz="1e-4"/>
    </inertial>
  </link>
  <gazebo reference="palm_link">
        <material>Gazebo/Black</material>
   </gazebo>
  <!-- ============================================================================= -->
  <!-- FINGERS -->
  <!-- RIGHT HAND due to which finger is number 0 -->
  <!-- for LEFT HAND switch the sign of the **offset_origin_y** and **finger_angle_r** parameters-->
  <!-- [LINK 0, 4, 8] -->

  <link name="link_0.0">
    <visual>
      <geometry>
        <mesh filename="package://allegro_hand_description/meshes/link_0.0.STL"/>
      </geometry>
      <material name="black"/>
    </visual>
    <collision>
      <geometry>
        <box size="0.0196 0.0275 0.0164"/>
      </geometry>
       <origin rpy="0.0 0.0 0.0" xyz="0.0 0.0 0.0082"/>
    </collision>
    <inertial>
      <mass value="0.0119"/>
       <origin rpy="0.0 0.0 0.0" xyz="0.0 0.0 0.0"/>
      <inertia ixx="1.01666658333e-06" ixy="1e-4" ixz="1e-4" iyy="6.47677333333e-07" iyz="1e-4" izz="1.01666658333e-06"/>
    </inertial>
  </link>
  <joint name="joint_0" type="revolute">
    <axis xyz="0.0 0.0 1"/>
    <limit effort="15" lower="-0.47" upper="0.47" velocity="7"/>
    <parent link="palm_link"/>
    <child link="link_0.0"/>
    <origin rpy="-0.08726646255 0 1.70" xyz="0 0.0435 -0.001542"/>
      
  </joint>
  <transmission name="tran0">
    <type>transmission_interface/SimpleTransmission</type>
    <joint name="joint_0">
      <hardwareInterface>hardware_interface/EffortJointInterface</hardwareInterface>
    </joint>
    <actuator name="motor0">
        
      <mechanicalReduction>1</mechanicalReduction>
    </actuator>
  </transmission>
  <!-- [LINK 1, 5, 9] -->
  <link name="link_1.0">
    <visual>
      <geometry>
        <mesh filename="package://allegro_hand_description/meshes/link_1.0.STL"/>
      </geometry>
      <material name="black"/>
    </visual>
    <collision>
      <geometry>
        <box size="0.0196 0.0275 0.054"/>
      </geometry>
       <origin rpy="0.0 0.0 0.0" xyz="0.0 0.0 0.027"/>
    </collision>
    <inertial>
      <mass value="0.065"/>
       <origin rpy="0.0 0.0 0.0" xyz="0.0 0.0 0.0"/>
      <inertia ixx="7.95654166667e-05" ixy="1.7199e-05" ixz="8.75875e-06" iyy="2.47088833333e-05" iyz="2.413125e-05" izz="7.95654166667e-05"/>
    </inertial>
  </link>
  <joint name="joint_1" type="revolute">
    <limit effort="15" lower="-0.196" upper="1.61" velocity="7"/>
    <axis xyz="0 1 0"/>
    <parent link="link_0.0"/>
    <child link="link_1.0"/>
    <origin xyz="0.0 0.0 0.0164"/>
      
  </joint>
  <transmission name="tran1">
    <type>transmission_interface/SimpleTransmission</type>
    <joint name="joint_1">
      <hardwareInterface>hardware_interface/EffortJointInterface</hardwareInterface>
    </joint>
    <actuator name="motor1">
        
      <mechanicalReduction>1</mechanicalReduction>
    </actuator>
  </transmission>

  <gazebo reference="link_0.0">
        <material>Gazebo/Black</material>
   </gazebo>
  <gazebo reference="link_1.0">
        <material>Gazebo/Black</material>
   </gazebo>
  <!-- [LINK 2, 6, 10]-->
  <link name="link_2.0">
    <visual>
      <geometry>
        <mesh filename="package://allegro_hand_description/meshes/link_2.0.STL"/>
      </geometry>
      <material name="black"/>
    </visual>
    <collision>
      <geometry>
        <box size="0.0196 0.0275 0.0384"/>
      </geometry>
       <origin rpy="0.0 0.0 0.0" xyz="0.0 0.0 0.0192"/>
    </collision>
    <inertial>
      <mass value="0.0355"/>
       <origin rpy="0.0 0.0 0.0" xyz="0.0 0.0 0.0"/>
      <inertia ixx="2.63979183333e-05" ixy="6.67968e-06" ixz="4.783625e-06" iyy="1.34948516667e-05" iyz="9.372e-06" izz="2.63979183333e-05"/>
    </inertial>
  </link>
  <joint name="joint_2" type="revolute">
    <axis xyz="0 1 0"/>
    <limit effort="15" lower="-0.174" upper="1.709" velocity="7"/>
    <parent link="link_1.0"/>
    <child link="link_2.0"/>
    <origin xyz="0.0 0.0 0.054"/>
      
  </joint>
  <transmission name="tran2">
    <type>transmission_interface/SimpleTransmission</type>
    <joint name="joint_2">
      <hardwareInterface>hardware_interface/EffortJointInterface</hardwareInterface>
    </joint>
    <actuator name="motor2">
        
      <mechanicalReduction>1</mechanicalReduction>
    </actuator>
  </transmission>
  <!-- [LINK 3, 7, 11] -->
  <link name="link_3.0">
    <visual>
      <geometry>
        <mesh filename="package://allegro_hand_description/meshes/link_3.0.STL"/>
      </geometry>
      <material name="black"/>
    </visual>
    <collision>
      <geometry>
        <box size="0.0196 0.0275 0.0267"/>
      </geometry>
       <origin rpy="0.0 0.0 0.0" xyz="0.0 0.0 0.01335"/>
    </collision>
    <inertial>
      <mass value="0.0096"/>
       <origin rpy="0.0 0.0 0.0" xyz="0.0 0.0 0.0"/>
      <inertia ixx="4.701248e-06" ixy="1.255968e-06" ixz="1.2936e-06" iyy="3.649312e-06" iyz="1.7622e-06" izz="4.701248e-06"/>
    </inertial>
  </link>
  <joint name="joint_3" type="revolute">
    <axis xyz="0 1 0"/>
    <limit effort="15" lower="-0.227" upper="1.618" velocity="7"/>
    <parent link="link_2.0"/>
    <child link="link_3.0"/>
    <origin xyz="0.0 0.0 0.0384"/>
      
  </joint>
  <transmission name="tran3">
    <type>transmission_interface/SimpleTransmission</type>
    <joint name="joint_3">
      <hardwareInterface>hardware_interface/EffortJointInterface</hardwareInterface>
    </joint>
    <actuator name="motor3">
        
      <mechanicalReduction>1</mechanicalReduction>
    </actuator>
  </transmission>
  <!-- [FINGER TIP] -->
  <link name="link_3.0_tip">
    <visual>
      <geometry>
        <mesh filename="package://allegro_hand_description/meshes/link_3.0_tip.STL"/>
      </geometry>
      <material name="white">
        <color rgba=".9 .9 .9 1"/>
      </material>
    </visual>
    <collision>
      <geometry>
        <sphere radius="0.012"/>
      </geometry>
    </collision>
    <inertial>
      <mass value="0.0168"/>
       <origin rpy="0.0 0.0 0.0" xyz="0.0 0.0 0.0"/>
      <inertia ixx="9.68e-07" ixy="1e-4" ixz="1e-4" iyy="9.68e-07" iyz="1e-4" izz="9.68e-07"/>
    </inertial>
  </link>
  <joint name="joint_3_tip" type="fixed">
    <parent link="link_3.0"/>
    <child link="link_3.0_tip"/>
     <origin rpy="0.0 0.0 0.0" xyz="0.0 0.0 0.0267"/>
  </joint>
  <!-- [LINK 0, 4, 8] -->
  <link name="link_4.0">
    <visual>
      <geometry>
        <mesh filename="package://allegro_hand_description/meshes/link_0.0.STL"/>
      </geometry>
      <material name="black"/>
    </visual>
    <collision>
      <geometry>
        <box size="0.0196 0.0275 0.0164"/>
      </geometry>
       <origin rpy="0.0 0.0 0.0" xyz="0.0 0.0 0.0082"/>
    </collision>
    <inertial>
      <mass value="0.0119"/>
       <origin rpy="0.0 0.0 0.0" xyz="0.0 0.0 0.0"/>
      <inertia ixx="1.01666658333e-06" ixy="1e-4" ixz="1e-4" iyy="6.47677333333e-07" iyz="1e-4" izz="1.01666658333e-06"/>
    </inertial>
  </link>
  <joint name="joint_4" type="revolute">
    <axis xyz="0.0 0.0 1"/>
    <limit effort="15" lower="-0.47" upper="0.47" velocity="7"/>
    <parent link="palm_link"/>
    <child link="link_4.0"/>
    <origin rpy="0.0 0 1.70" xyz="0.0 0.0 0.0007"/>
      
  </joint>
  <transmission name="tran4">
    <type>transmission_interface/SimpleTransmission</type>
    <joint name="joint_4">
      <hardwareInterface>hardware_interface/EffortJointInterface</hardwareInterface>
    </joint>
    <actuator name="motor4">
        
      <mechanicalReduction>1</mechanicalReduction>
    </actuator>
  </transmission>
  <!-- [LINK 1, 5, 9] -->
  <link name="link_5.0">
    <visual>
      <geometry>
        <mesh filename="package://allegro_hand_description/meshes/link_1.0.STL"/>
      </geometry>
      <material name="black"/>
    </visual>
    <collision>
      <geometry>
        <box size="0.0196 0.0275 0.054"/>
      </geometry>
       <origin rpy="0.0 0.0 0.0" xyz="0.0 0.0 0.027"/>
    </collision>
    <inertial>
      <mass value="0.065"/>
       <origin rpy="0.0 0.0 0.0" xyz="0.0 0.0 0.0"/>
      <inertia ixx="7.95654166667e-05" ixy="1.7199e-05" ixz="8.75875e-06" iyy="2.47088833333e-05" iyz="2.413125e-05" izz="7.95654166667e-05"/>
    </inertial>
  </link>
  <joint name="joint_5" type="revolute">
    <limit effort="15" lower="-0.196" upper="1.61" velocity="7"/>
    <axis xyz="0 1 0"/>
    <parent link="link_4.0"/>
    <child link="link_5.0"/>
    <origin xyz="0.0 0.0 0.0164"/>
      
  </joint>
  <transmission name="tran5">
    <type>transmission_interface/SimpleTransmission</type>
    <joint name="joint_5">
      <hardwareInterface>hardware_interface/EffortJointInterface</hardwareInterface>
    </joint>
    <actuator name="motor5">
        
      <mechanicalReduction>1</mechanicalReduction>
    </actuator>
  </transmission>
  <!-- [LINK 2, 6, 10]-->
  <link name="link_6.0">
    <visual>
      <geometry>
        <mesh filename="package://allegro_hand_description/meshes/link_2.0.STL"/>
      </geometry>
      <material name="black"/>
    </visual>
    <collision>
      <geometry>
        <box size="0.0196 0.0275 0.0384"/>
      </geometry>
       <origin rpy="0.0 0.0 0.0" xyz="0.0 0.0 0.0192"/>
    </collision>
    <inertial>
      <mass value="0.0355"/>
       <origin rpy="0.0 0.0 0.0" xyz="0.0 0.0 0.0"/>
      <inertia ixx="2.63979183333e-05" ixy="6.67968e-06" ixz="4.783625e-06" iyy="1.34948516667e-05" iyz="9.372e-06" izz="2.63979183333e-05"/>
    </inertial>
  </link>
  <joint name="joint_6" type="revolute">
    <axis xyz="0 1 0"/>
    <limit effort="15" lower="-0.174" upper="1.709" velocity="7"/>
    <parent link="link_5.0"/>
    <child link="link_6.0"/>
    <origin xyz="0.0 0.0 0.054"/>
      
  </joint>
  <transmission name="tran6">
    <type>transmission_interface/SimpleTransmission</type>
    <joint name="joint_6">
      <hardwareInterface>hardware_interface/EffortJointInterface</hardwareInterface>
    </joint>
    <actuator name="motor6">
        
      <mechanicalReduction>1</mechanicalReduction>
    </actuator>
  </transmission>
  <!-- [LINK 3, 7, 11] -->
  <link name="link_7.0">
    <visual>
      <geometry>
        <mesh filename="package://allegro_hand_description/meshes/link_3.0.STL"/>
      </geometry>
      <material name="black"/>
    </visual>
    <collision>
      <geometry>
        <box size="0.0196 0.0275 0.0267"/>
      </geometry>
       <origin rpy="0.0 0.0 0.0" xyz="0.0 0.0 0.01335"/>
    </collision>
    <inertial>
      <mass value="0.0096"/>
       <origin rpy="0.0 0.0 0.0" xyz="0.0 0.0 0.0"/>
      <inertia ixx="4.701248e-06" ixy="1.255968e-06" ixz="1.2936e-06" iyy="3.649312e-06" iyz="1.7622e-06" izz="4.701248e-06"/>
    </inertial>
  </link>
  <joint name="joint_7" type="revolute">
    <axis xyz="0 1 0"/>
    <limit effort="15" lower="-0.227" upper="1.618" velocity="7"/>
    <parent link="link_6.0"/>
    <child link="link_7.0"/>
    <origin xyz="0.0 0.0 0.0384"/>
      
  </joint>
  <transmission name="tran7">
    <type>transmission_interface/SimpleTransmission</type>
    <joint name="joint_7">
      <hardwareInterface>hardware_interface/EffortJointInterface</hardwareInterface>
    </joint>
    <actuator name="motor7">
        
      <mechanicalReduction>1</mechanicalReduction>
    </actuator>
  </transmission>
  <!-- [FINGER TIP] -->
  <link name="link_7.0_tip">
    <visual>
      <geometry>
        <mesh filename="package://allegro_hand_description/meshes/link_3.0_tip.STL"/>
      </geometry>
      <material name="white">
        <color rgba=".9 .9 .9 1"/>
      </material>
    </visual>
    <collision>
      <geometry>
        <sphere radius="0.012"/>
      </geometry>
    </collision>
    <inertial>
      <mass value="0.0168"/>
       <origin rpy="0.0 0.0 0.0" xyz="0.0 0.0 0.0"/>
      <inertia ixx="9.68e-07" ixy="1e-4" ixz="1e-4" iyy="9.68e-07" iyz="1e-4" izz="9.68e-07"/>
    </inertial>
  </link>
  <joint name="joint_7_tip" type="fixed">
    <parent link="link_7.0"/>
    <child link="link_7.0_tip"/>
     <origin rpy="0.0 0.0 0.0" xyz="0.0 0.0 0.0267"/>
  </joint>
  <!-- [LINK 0, 4, 8] -->
  <link name="link_8.0">
    <visual>
      <geometry>
        <mesh filename="package://allegro_hand_description/meshes/link_0.0.STL"/>
      </geometry>
      <material name="black"/>
    </visual>
    <collision>
      <geometry>
        <box size="0.0196 0.0275 0.0164"/>
      </geometry>
       <origin rpy="0.0 0.0 0.0" xyz="0.0 0.0 0.0082"/>
    </collision>
    <inertial>
      <mass value="0.0119"/>
       <origin rpy="0.0 0.0 0.0" xyz="0.0 0.0 0.0"/>
      <inertia ixx="1.01666658333e-06" ixy="1e-4" ixz="1e-4" iyy="6.47677333333e-07" iyz="1e-4" izz="1.01666658333e-06"/>
    </inertial>
  </link>
  <joint name="joint_8" type="revolute">
    <axis xyz="0.0 0.0 1"/>
    <limit effort="15" lower="-0.47" upper="0.47" velocity="7"/>
    <parent link="palm_link"/>
    <child link="link_8.0"/>
    <origin rpy="0.08726646255 0 1.70" xyz="0 -0.0435 -0.001542"/>
      
  </joint>
  <transmission name="tran8">
    <type>transmission_interface/SimpleTransmission</type>
    <joint name="joint_8">
      <hardwareInterface>hardware_interface/EffortJointInterface</hardwareInterface>
    </joint>
    <actuator name="motor8">
      <mechanicalReduction>1</mechanicalReduction>
    </actuator>
  </transmission>
  <!-- [LINK 1, 5, 9] -->
  <link name="link_9.0">
    <visual>
      <geometry>
        <mesh filename="package://allegro_hand_description/meshes/link_1.0.STL"/>
      </geometry>
      <material name="black"/>
    </visual>
    <collision>
      <geometry>
        <box size="0.0196 0.0275 0.054"/>
      </geometry>
       <origin rpy="0.0 0.0 0.0" xyz="0.0 0.0 0.027"/>
    </collision>
    <inertial>
      <mass value="0.065"/>
       <origin rpy="0.0 0.0 0.0" xyz="0.0 0.0 0.0"/>
      <inertia ixx="7.95654166667e-05" ixy="1.7199e-05" ixz="8.75875e-06" iyy="2.47088833333e-05" iyz="2.413125e-05" izz="7.95654166667e-05"/>
    </inertial>
  </link>
  <joint name="joint_9" type="revolute">
    <limit effort="15" lower="-0.196" upper="1.61" velocity="7"/>
    <axis xyz="0 1 0"/>
    <parent link="link_8.0"/>
    <child link="link_9.0"/>
    <origin xyz="0.0 0.0 0.0164"/>
      
  </joint>
  <transmission name="tran9">
    <type>transmission_interface/SimpleTransmission</type>
    <joint name="joint_9">
      <hardwareInterface>hardware_interface/EffortJointInterface</hardwareInterface>
    </joint>
    <actuator name="motor9">
        
      <mechanicalReduction>1</mechanicalReduction>
    </actuator>
  </transmission>
  <!-- [LINK 2, 6, 10]-->
  <link name="link_10.0">
    <visual>
      <geometry>
        <mesh filename="package://allegro_hand_description/meshes/link_2.0.STL"/>
      </geometry>
      <material name="black"/>
    </visual>
    <collision>
      <geometry>
        <box size="0.0196 0.0275 0.0384"/>
      </geometry>
       <origin rpy="0.0 0.0 0.0" xyz="0.0 0.0 0.0192"/>
    </collision>
    <inertial>
      <mass value="0.0355"/>
       <origin rpy="0.0 0.0 0.0" xyz="0.0 0.0 0.0"/>
      <inertia ixx="2.63979183333e-05" ixy="6.67968e-06" ixz="4.783625e-06" iyy="1.34948516667e-05" iyz="9.372e-06" izz="2.63979183333e-05"/>
    </inertial>
  </link>
  <joint name="joint_10" type="revolute">
    <axis xyz="0 1 0"/>
    <limit effort="15" lower="-0.174" upper="1.709" velocity="7"/>
    <parent link="link_9.0"/>
    <child link="link_10.0"/>
    <origin xyz="0.0 0.0 0.054"/>
      
  </joint>
  <transmission name="tran10">
    <type>transmission_interface/SimpleTransmission</type>
    <joint name="joint_10">
      <hardwareInterface>hardware_interface/EffortJointInterface</hardwareInterface>
    </joint>
    <actuator name="motor10">
        
      <mechanicalReduction>1</mechanicalReduction>
    </actuator>
  </transmission>
  <!-- [LINK 3, 7, 11] -->
  <link name="link_11.0">
    <visual>
      <geometry>
        <mesh filename="package://allegro_hand_description/meshes/link_3.0.STL"/>
      </geometry>
      <material name="black"/>
    </visual>
    <collision>
      <geometry>
        <box size="0.0196 0.0275 0.0267"/>
      </geometry>
       <origin rpy="0.0 0.0 0.0" xyz="0.0 0.0 0.01335"/>
    </collision>
    <inertial>
      <mass value="0.0096"/>
       <origin rpy="0.0 0.0 0.0" xyz="0.0 0.0 0.0"/>
      <inertia ixx="4.701248e-06" ixy="1.255968e-06" ixz="1.2936e-06" iyy="3.649312e-06" iyz="1.7622e-06" izz="4.701248e-06"/>
    </inertial>
  </link>
  <joint name="joint_11" type="revolute">
    <axis xyz="0 1 0"/>
    <limit effort="15" lower="-0.227" upper="1.618" velocity="7"/>
    <parent link="link_10.0"/>
    <child link="link_11.0"/>
    <origin xyz="0.0 0.0 0.0384"/>
      
  </joint>
  <transmission name="tran11">
    <type>transmission_interface/SimpleTransmission</type>
    <joint name="joint_11">
      <hardwareInterface>hardware_interface/EffortJointInterface</hardwareInterface>
    </joint>
    <actuator name="motor11">
        
      <mechanicalReduction>1</mechanicalReduction>
    </actuator>
  </transmission>
  <!-- [FINGER TIP] -->
  <link name="link_11.0_tip">
    <visual>
      <geometry>
        <mesh filename="package://allegro_hand_description/meshes/link_3.0_tip.STL"/>
      </geometry>
      <material name="white">
        <color rgba=".9 .9 .9 1"/>
      </material>
    </visual>
    <collision>
      <geometry>
        <sphere radius="0.012"/>
      </geometry>
    </collision>
    <inertial>
      <mass value="0.0168"/>
       <origin rpy="0.0 0.0 0.0" xyz="0.0 0.0 0.0"/>
      <inertia ixx="9.68e-07" ixy="1e-4" ixz="1e-4" iyy="9.68e-07" iyz="1e-4" izz="9.68e-07"/>
    </inertial>
  </link>
  <joint name="joint_11_tip" type="fixed">
    <parent link="link_11.0"/>
    <child link="link_11.0_tip"/>
     <origin rpy="0.0 0.0 0.0" xyz="0.0 0.0 0.0267"/>
  </joint>
  <!-- THUMB -->
  <!-- [LINK 12] -->
  <link name="link_12.0">
    <visual>
      <geometry>
        <mesh filename="package://allegro_hand_description/meshes/link_12.0_right.STL"/>
      </geometry>
      <material name="black">
        <color rgba=".2 .2 .2 1"/>
      </material>
    </visual>
    <collision>
      <geometry>
        <box size="0.0358 0.034 0.0455"/>
      </geometry>
       <origin rpy="0.0 0.0 0.0" xyz="-0.0179 0.009 0.0145"/>
    </collision>
    <inertial>
      <mass value="0.0176"/>
       <origin rpy="0.0 0.0 0.0" xyz="0.0 0.0 0.0"/>
      <inertia ixx="1.89273333333e-5" ixy="7.16716e-06" ixz="5.35568e-06" iyy="1.43008213333e-05" iyz="6.8068e-06" izz="1.89273333333e-05"/>
    </inertial>
  </link>
  <joint name="joint_12" type="revolute">
    <axis xyz="-1 0 0"/>
    <limit effort="15" lower="0.263" upper="1.396" velocity="7"/>
    <parent link="palm_link"/>
    <child link="link_12.0"/>
    <origin rpy="0 -1.65806278845 -1.5707963259" xyz="-0.0182 0.019333 -0.045987"/>
      
  </joint>
  <transmission name="tran12">
    <type>transmission_interface/SimpleTransmission</type>
    <joint name="joint_12">
      <hardwareInterface>hardware_interface/EffortJointInterface</hardwareInterface>
    </joint>
    <actuator name="motor12">
        
      <mechanicalReduction>1</mechanicalReduction>
    </actuator>
  </transmission>
  <!-- [LINK 13] -->
  <link name="link_13.0">
    <visual>
      <geometry>
        <mesh filename="package://allegro_hand_description/meshes/link_13.0.STL"/>
      </geometry>
      <material name="black">
        <color rgba=".2 .2 .2 1"/>
      </material>
    </visual>
    <collision>
      <geometry>
        <box size="0.0196 0.0275 0.0177"/>
      </geometry>
       <origin rpy="0.0 0.0 0.0" xyz="0.0 0.0 0.00885"/>
    </collision>
    <inertial>
      <mass value="0.0119"/>
       <origin rpy="0.0 0.0 0.0" xyz="0.0 0.0 0.0"/>
      <inertia ixx="4.24250866667e-06" ixy="1.032087e-06" ixz="1.603525e-06" iyy="4.52362633333e-06" iyz="1.44808125e-06" izz="4.24250866667e-06"/>
    </inertial>
  </link>
  <joint name="joint_13" type="revolute">
    <axis xyz="0.0 0.0 1"/>
    <limit effort="15" lower="-0.105" upper="1.163" velocity="7"/>
    <parent link="link_12.0"/>
    <child link="link_13.0"/>
    <origin xyz="-0.027 0.005 0.0399"/>
      
  </joint>
  <transmission name="tran13">
    <type>transmission_interface/SimpleTransmission</type>
    <joint name="joint_13">
      <hardwareInterface>hardware_interface/EffortJointInterface</hardwareInterface>
    </joint>
    <actuator name="motor13">
        
      <mechanicalReduction>1</mechanicalReduction>
    </actuator>
  </transmission>
  <!-- [LINK 14] -->
  <link name="link_14.0">
    <visual>
      <geometry>
        <mesh filename="package://allegro_hand_description/meshes/link_14.0.STL"/>
      </geometry>
      <material name="black">
                </material>
    </visual>
    <collision>
      <geometry>
        <box size="0.0196 0.0275 0.0514"/>
      </geometry>
       <origin rpy="0.0 0.0 0.0" xyz="0.0 0.0 0.0257"/>
    </collision>
    <inertial>
      <mass value="0.038"/>
       <origin rpy="0.0 0.0 0.0" xyz="0.0 0.0 0.0"/>
      <inertia ixx="4.30439933333e-05" ixy="9.57068e-06" ixz="5.1205e-06" iyy="1.44451933333e-05" iyz="1.342825e-05" izz="4.30439933333e-05"/>
    </inertial>
  </link>
  <joint name="joint_14" type="revolute">
    <axis xyz="0 1 0"/>
    <limit effort="15" lower="-0.189" upper="1.644" velocity="7"/>
    <parent link="link_13.0"/>
    <child link="link_14.0"/>
    <origin xyz="0.0 0.0 0.0177"/>
      
  </joint>
  <transmission name="tran14">
    <type>transmission_interface/SimpleTransmission</type>
    <joint name="joint_14">
      <hardwareInterface>hardware_interface/EffortJointInterface</hardwareInterface>
    </joint>
    <actuator name="motor14">
        
      <mechanicalReduction>1</mechanicalReduction>
    </actuator>
  </transmission>
  <!-- [LINK 15] -->
  <link name="link_15.0">
    <visual>
      <geometry>
        <mesh filename="package://allegro_hand_description/meshes/link_15.0.STL"/>
      </geometry>
      <material name="black" />
    </visual>
    <collision>
      <geometry>
        <box size="0.0196 0.0275 0.0423"/>
      </geometry>
       <origin rpy="0.0 0.0 0.0" xyz="0.0 0.0 0.02115"/>
    </collision>
    <inertial>
      <mass value="0.0388"/>
       <origin rpy="0.0 0.0 0.0" xyz="0.0 0.0 0.0"/>
      <inertia ixx="3.29223173333e-05" ixy="8.042076e-06" ixz="5.2283e-06" iyy="1.47493026667e-5" iyz="1.1283525e-5" izz="3.29223173333e-05"/>
    </inertial>
  </link>
  <joint name="joint_15" type="revolute">
    <axis xyz="0 1 0"/>
    <limit effort="15" lower="-0.162" upper="1.719" velocity="7"/>
    <parent link="link_14.0"/>
    <child link="link_15.0"/>
    <origin xyz="0.0 0.0 0.0514"/>
  </joint>
  <transmission name="tran15">
    <type>transmission_interface/SimpleTransmission</type>
    <joint name="joint_15">
      <hardwareInterface>hardware_interface/EffortJointInterface</hardwareInterface>
    </joint>
    <actuator name="motor15">
        
      <mechanicalReduction>1</mechanicalReduction>
    </actuator>
  </transmission>
  <!-- [FINGER TIP] -->
  <!--link name="link_15.0_tip">
    <visual>
      <geometry>
        <mesh filename="package://allegro_hand_description/meshes/link_15.0_tip.STL"/>
      </geometry>
      <material name="white">
        <color rgba=".9 .9 .9 1"/>
      </material>
    </visual>
    <collision>
      <geometry>
        <sphere radius="0.012"/>
      </geometry>
       <origin rpy="0.0 0.0 0.0" xyz="0.0 0.0 0.0"/>
    </collision>
    <inertial>
      <mass value="0.0168"/>
       <origin rpy="0.0 0.0 0.0" xyz="0.0 0.0 0.0"/>
      <inertia ixx="9.68e-07" ixy="1e-4" ixz="1e-4" iyy="9.68e-07" iyz="1e-4" izz="9.68e-07"/>
    </inertial>
  </link>
  <joint name="joint_15_tip" type="fixed">
    <parent link="link_15.0"/>
    <child link="link_15.0_tip"/>
     <origin rpy="0.0 0.0 0.0" xyz="0.0 0.0 0.0423"/>
  </joint-->
  <gazebo>
    <plugin name="gazebo_ros_control" filename="libgazebo_ros_control.so">
      <robotNamespace>/</robotNamespace>
    </plugin>
  </gazebo>

  <!-- ============================================================================= -->
  <!-- THUMB MACRO -->
  <!-- END THUMB MACRO -->
  <!-- THREE FINGER MACRO -->
  <!-- [[END]] THREE FINGER MACRO -->
</robot>
