<?xml version="1.0" ?>
<!-- =================================================================================== -->
<!-- |    This document was autogenerated by xacro from /home/chenxunman/6/src/allegro_hand_description/urdf/allegro_hand_description_left.xacro | -->
<!-- |    EDITING THIS FILE BY HAND IS NOT RECOMMENDED                                 | -->
<!-- =================================================================================== -->
<robot name="allegro_hand_left" xmlns:xacro="http://ros.org/wiki/xacro">
  <!--
rosrun xacro xacro.py allegro_hand_description_right.urdf.xacro > allegro_hand_description_right.urdf
roslaunch launchers/fuerte/allegro_hand_jgui_right_virtual.launch 
-->
  <!-- ======================== BASE PARAMS ========================= -->
  <!-- ======================== FINGER PARAMS ======================== -->
  <!-- full height from joint to tip. when used,
the radius of the finger tip sphere will be subtracted
and one fixed link will be added for the tip. -->
  <!--0.0435,   0.044981-->
  <!--0.002298-->
  <!--0.002298-->
  <!-- ========================= THUMB PARAMS ========================= -->
  <!-- ========================= LIMITS ========================= -->
  <!-- ============================================================================= -->
  <!-- ============================================================================= -->
  <!-- ============================================================================= -->
  <!-- BASE -->
  <link name="left_palm_link">
    <visual>
      <geometry>
        <mesh filename="package://allegro_hand_description/meshes/base_link_left.STL"/>
      </geometry>
      <!-- LEFT -->
      <origin rpy="-1.5707963259 0 0" xyz="0 0 0 "/>
      <!-- RIGHT -->
      <!--<origin rpy="0.0 0.0 0.0" xyz="0 0 0 "/>-->
      <material name="black">
        <color rgba="0.2 0.2 0.2 1"/>
      </material>
    </visual>
    <collision>
      <origin rpy="0.0 0.0 0.0" xyz="-0.009300 0 -0.0475"/>
      <geometry>
        <box size="0.0408 0.1130 0.095"/>
      </geometry>
    </collision>
    <inertial>
      <origin rpy="0.0 0.0 0.0" xyz="0.0 0.0 0.0475"/>
      <mass value="0.4154"/>
      <inertia ixx="1e-4" ixy="0.0" ixz="0.0" iyy="1e-4" iyz="0.0" izz="1e-4"/>
    </inertial>
  </link>
  <!-- ============================================================================= -->
  <!-- FINGERS -->
  <!-- RIGHT HAND due to which finger is number 0 -->
  <!-- for LEFT HAND switch the sign of the **offset_origin_y** and **finger_angle_r** parameters-->
  <!-- [LINK 0, 4, 8] -->
  <link name="left_link_8.0">
    <visual>
      <geometry>
        <mesh filename="package://allegro_hand_description/meshes/link_0.0.STL"/>
      </geometry>
      <material name="black"/>
    </visual>
    <collision>
      <geometry>
        <box size="0.0196 0.0275 0.0164"/>
      </geometry>
      <origin rpy="0.0 0.0 0.0" xyz="0 0 0.0082"/>
    </collision>
    <inertial>
      <mass value="0.0119"/>
      <origin rpy="0 0 0" xyz="0.0 0.0 0.0"/>
      <inertia ixx="1.01666658333e-06" ixy="0.0" ixz="0.0" iyy="6.47677333333e-07" iyz="0.0" izz="1.01666658333e-06"/>
    </inertial>
  </link>
  <joint name="left_joint_8" type="revolute">
    <axis xyz="0 0 1"/>
    <limit effort="0" lower="-0.47" upper="0.47" velocity="0"/>
    <parent link="left_palm_link"/>
    <child link="left_link_8.0"/>
    <origin rpy="-0.08726646255 0 0" xyz="0 0.0435 -0.001542"/>
    <dynamics friction="10"/>
  </joint>
  <transmission name="tran1">
    <type>transmission_interface/SimpleTransmission</type>
    <joint name="left_joint_8">
      <hardwareInterface>EffortJointInterface</hardwareInterface>
    </joint>
    <actuator name="motor1">
      <hardwareInterface>EffortJointInterface</hardwareInterface>
      <mechanicalReduction>1</mechanicalReduction>
    </actuator>
  </transmission>
  <!-- [LINK 1, 5, 9] -->
  <link name="left_link_9.0">
    <visual>
      <geometry>
        <mesh filename="package://allegro_hand_description/meshes/link_1.0.STL"/>
      </geometry>
      <material name="black"/>
    </visual>
    <collision>
      <geometry>
        <box size="0.0196 0.0275 0.054"/>
      </geometry>
      <origin rpy="0.0 0.0 0.0" xyz="0 0 0.027"/>
    </collision>
    <inertial>
      <mass value="0.065"/>
      <origin rpy="0 0 0" xyz="0.0 0.0 0.0"/>
      <inertia ixx="7.95654166667e-05" ixy="1.7199e-05" ixz="8.75875e-06" iyy="2.47088833333e-05" iyz="2.413125e-05" izz="7.95654166667e-05"/>
    </inertial>
  </link>
  <joint name="left_joint_9" type="revolute">
    <limit effort="0" lower="-0.196" upper="1.61" velocity="0"/>
    <axis xyz="0 1 0"/>
    <parent link="left_link_8.0"/>
    <child link="left_link_9.0"/>
    <origin xyz="0 0 0.0164"/>
    <dynamics friction="5"/>
  </joint>
  <transmission name="tran1">
    <type>transmission_interface/SimpleTransmission</type>
    <joint name="left_joint_9">
      <hardwareInterface>EffortJointInterface</hardwareInterface>
    </joint>
    <actuator name="motor1">
      <hardwareInterface>EffortJointInterface</hardwareInterface>
      <mechanicalReduction>1</mechanicalReduction>
    </actuator>
  </transmission>
  <!-- [LINK 2, 6, 10]-->
  <link name="left_link_10.0">
    <visual>
      <geometry>
        <mesh filename="package://allegro_hand_description/meshes/link_2.0.STL"/>
      </geometry>
      <material name="black"/>
    </visual>
    <collision>
      <geometry>
        <box size="0.0196 0.0275 0.0384"/>
      </geometry>
      <origin rpy="0.0 0.0 0.0" xyz="0 0 0.0192"/>
    </collision>
    <inertial>
      <mass value="0.0355"/>
      <origin rpy="0 0 0" xyz="0.0 0.0 0.0"/>
      <inertia ixx="2.63979183333e-05" ixy="6.67968e-06" ixz="4.783625e-06" iyy="1.34948516667e-05" iyz="9.372e-06" izz="2.63979183333e-05"/>
    </inertial>
  </link>
  <joint name="left_joint_10" type="revolute">
    <axis xyz="0 1 0"/>
    <limit effort="0" lower="-0.174" upper="1.709" velocity="0"/>
    <parent link="left_link_9.0"/>
    <child link="left_link_10.0"/>
    <origin xyz="0 0 0.054"/>
    <dynamics friction="10"/>
  </joint>
  <transmission name="tran1">
    <type>transmission_interface/SimpleTransmission</type>
    <joint name="left_joint_10">
      <hardwareInterface>EffortJointInterface</hardwareInterface>
    </joint>
    <actuator name="motor1">
      <hardwareInterface>EffortJointInterface</hardwareInterface>
      <mechanicalReduction>1</mechanicalReduction>
    </actuator>
  </transmission>
  <!-- [LINK 3, 7, 11] -->
  <link name="left_link_11.0">
    <visual>
      <geometry>
        <mesh filename="package://allegro_hand_description/meshes/link_3.0.STL"/>
      </geometry>
      <material name="black"/>
    </visual>
    <collision>
      <geometry>
        <box size="0.0196 0.0275 0.0267"/>
      </geometry>
      <origin rpy="0.0 0.0 0.0" xyz="0 0 0.01335"/>
    </collision>
    <inertial>
      <mass value="0.0096"/>
      <origin rpy="0 0 0" xyz="0.0 0.0 0.0"/>
      <inertia ixx="4.701248e-06" ixy="1.255968e-06" ixz="1.2936e-06" iyy="3.649312e-06" iyz="1.7622e-06" izz="4.701248e-06"/>
    </inertial>
  </link>
  <joint name="left_joint_11" type="revolute">
    <axis xyz="0 1 0"/>
    <limit effort="0" lower="-0.227" upper="1.618" velocity="0"/>
    <parent link="left_link_10.0"/>
    <child link="left_link_11.0"/>
    <origin xyz="0 0 0.0384"/>
    <dynamics friction="12"/>
  </joint>
  <transmission name="tran1">
    <type>transmission_interface/SimpleTransmission</type>
    <joint name="left_joint_11">
      <hardwareInterface>EffortJointInterface</hardwareInterface>
    </joint>
    <actuator name="motor1">
      <hardwareInterface>EffortJointInterface</hardwareInterface>
      <mechanicalReduction>1</mechanicalReduction>
    </actuator>
  </transmission>
  <!-- [FINGER TIP] -->
  <link name="left_link_11.0_tip">
    <visual>
      <geometry>
        <mesh filename="package://allegro_hand_description/meshes/link_3.0_tip.STL"/>
      </geometry>
      <material name="white">
        <color rgba=".9 .9 .9 1"/>
      </material>
    </visual>
    <collision>
      <geometry>
        <sphere radius="0.012"/>
      </geometry>
    </collision>
    <inertial>
      <mass value="0.0168"/>
      <origin rpy="0 0 0" xyz="0.0 0.0 0.0"/>
      <inertia ixx="9.68e-07" ixy="0.0" ixz="0.0" iyy="9.68e-07" iyz="0.0" izz="9.68e-07"/>
    </inertial>
  </link>
  <joint name="left_joint_11_tip" type="fixed">
    <parent link="left_link_11.0"/>
    <child link="left_link_11.0_tip"/>
    <origin rpy="0.0 0.0 0.0" xyz="0 0 0.0267"/>
  </joint>
  <!-- [LINK 0, 4, 8] -->
  <link name="left_link_4.0">
    <visual>
      <geometry>
        <mesh filename="package://allegro_hand_description/meshes/link_0.0.STL"/>
      </geometry>
      <material name="black"/>
    </visual>
    <collision>
      <geometry>
        <box size="0.0196 0.0275 0.0164"/>
      </geometry>
      <origin rpy="0.0 0.0 0.0" xyz="0 0 0.0082"/>
    </collision>
    <inertial>
      <mass value="0.0119"/>
      <origin rpy="0 0 0" xyz="0.0 0.0 0.0"/>
      <inertia ixx="1.01666658333e-06" ixy="0.0" ixz="0.0" iyy="6.47677333333e-07" iyz="0.0" izz="1.01666658333e-06"/>
    </inertial>
  </link>
  <joint name="left_joint_4" type="revolute">
    <axis xyz="0 0 1"/>
    <limit effort="0" lower="-0.47" upper="0.47" velocity="0"/>
    <parent link="left_palm_link"/>
    <child link="left_link_4.0"/>
    <origin rpy="0.0 0 0" xyz="0 0 0.0007"/>
    <dynamics friction="10"/>
  </joint>
  <transmission name="tran1">
    <type>transmission_interface/SimpleTransmission</type>
    <joint name="left_joint_4">
      <hardwareInterface>EffortJointInterface</hardwareInterface>
    </joint>
    <actuator name="motor1">
      <hardwareInterface>EffortJointInterface</hardwareInterface>
      <mechanicalReduction>1</mechanicalReduction>
    </actuator>
  </transmission>
  <!-- [LINK 1, 5, 9] -->
  <link name="left_link_5.0">
    <visual>
      <geometry>
        <mesh filename="package://allegro_hand_description/meshes/link_1.0.STL"/>
      </geometry>
      <material name="black"/>
    </visual>
    <collision>
      <geometry>
        <box size="0.0196 0.0275 0.054"/>
      </geometry>
      <origin rpy="0.0 0.0 0.0" xyz="0 0 0.027"/>
    </collision>
    <inertial>
      <mass value="0.065"/>
      <origin rpy="0 0 0" xyz="0.0 0.0 0.0"/>
      <inertia ixx="7.95654166667e-05" ixy="1.7199e-05" ixz="8.75875e-06" iyy="2.47088833333e-05" iyz="2.413125e-05" izz="7.95654166667e-05"/>
    </inertial>
  </link>
  <joint name="left_joint_5" type="revolute">
    <limit effort="0" lower="-0.196" upper="1.61" velocity="0"/>
    <axis xyz="0 1 0"/>
    <parent link="left_link_4.0"/>
    <child link="left_link_5.0"/>
    <origin xyz="0 0 0.0164"/>
    <dynamics friction="5"/>
  </joint>
  <transmission name="tran1">
    <type>transmission_interface/SimpleTransmission</type>
    <joint name="left_joint_5">
      <hardwareInterface>EffortJointInterface</hardwareInterface>
    </joint>
    <actuator name="motor1">
      <hardwareInterface>EffortJointInterface</hardwareInterface>
      <mechanicalReduction>1</mechanicalReduction>
    </actuator>
  </transmission>
  <!-- [LINK 2, 6, 10]-->
  <link name="left_link_6.0">
    <visual>
      <geometry>
        <mesh filename="package://allegro_hand_description/meshes/link_2.0.STL"/>
      </geometry>
      <material name="black"/>
    </visual>
    <collision>
      <geometry>
        <box size="0.0196 0.0275 0.0384"/>
      </geometry>
      <origin rpy="0.0 0.0 0.0" xyz="0 0 0.0192"/>
    </collision>
    <inertial>
      <mass value="0.0355"/>
      <origin rpy="0 0 0" xyz="0.0 0.0 0.0"/>
      <inertia ixx="2.63979183333e-05" ixy="6.67968e-06" ixz="4.783625e-06" iyy="1.34948516667e-05" iyz="9.372e-06" izz="2.63979183333e-05"/>
    </inertial>
  </link>
  <joint name="left_joint_6" type="revolute">
    <axis xyz="0 1 0"/>
    <limit effort="0" lower="-0.174" upper="1.709" velocity="0"/>
    <parent link="left_link_5.0"/>
    <child link="left_link_6.0"/>
    <origin xyz="0 0 0.054"/>
    <dynamics friction="10"/>
  </joint>
  <transmission name="tran1">
    <type>transmission_interface/SimpleTransmission</type>
    <joint name="left_joint_6">
      <hardwareInterface>EffortJointInterface</hardwareInterface>
    </joint>
    <actuator name="motor1">
      <hardwareInterface>EffortJointInterface</hardwareInterface>
      <mechanicalReduction>1</mechanicalReduction>
    </actuator>
  </transmission>
  <!-- [LINK 3, 7, 11] -->
  <link name="left_link_7.0">
    <visual>
      <geometry>
        <mesh filename="package://allegro_hand_description/meshes/link_3.0.STL"/>
      </geometry>
      <material name="black"/>
    </visual>
    <collision>
      <geometry>
        <box size="0.0196 0.0275 0.0267"/>
      </geometry>
      <origin rpy="0.0 0.0 0.0" xyz="0 0 0.01335"/>
    </collision>
    <inertial>
      <mass value="0.0096"/>
      <origin rpy="0 0 0" xyz="0.0 0.0 0.0"/>
      <inertia ixx="4.701248e-06" ixy="1.255968e-06" ixz="1.2936e-06" iyy="3.649312e-06" iyz="1.7622e-06" izz="4.701248e-06"/>
    </inertial>
  </link>
  <joint name="left_joint_7" type="revolute">
    <axis xyz="0 1 0"/>
    <limit effort="0" lower="-0.227" upper="1.618" velocity="0"/>
    <parent link="left_link_6.0"/>
    <child link="left_link_7.0"/>
    <origin xyz="0 0 0.0384"/>
    <dynamics friction="12"/>
  </joint>
  <transmission name="tran1">
    <type>transmission_interface/SimpleTransmission</type>
    <joint name="left_joint_7">
      <hardwareInterface>EffortJointInterface</hardwareInterface>
    </joint>
    <actuator name="motor1">
      <hardwareInterface>EffortJointInterface</hardwareInterface>
      <mechanicalReduction>1</mechanicalReduction>
    </actuator>
  </transmission>
  <!-- [FINGER TIP] -->
  <link name="left_link_7.0_tip">
    <visual>
      <geometry>
        <mesh filename="package://allegro_hand_description/meshes/link_3.0_tip.STL"/>
      </geometry>
      <material name="white">
        <color rgba=".9 .9 .9 1"/>
      </material>
    </visual>
    <collision>
      <geometry>
        <sphere radius="0.012"/>
      </geometry>
    </collision>
    <inertial>
      <mass value="0.0168"/>
      <origin rpy="0 0 0" xyz="0.0 0.0 0.0"/>
      <inertia ixx="9.68e-07" ixy="0.0" ixz="0.0" iyy="9.68e-07" iyz="0.0" izz="9.68e-07"/>
    </inertial>
  </link>
  <joint name="left_joint_7_tip" type="fixed">
    <parent link="left_link_7.0"/>
    <child link="left_link_7.0_tip"/>
    <origin rpy="0.0 0.0 0.0" xyz="0 0 0.0267"/>
  </joint>
  <!-- [LINK 0, 4, 8] -->
  <link name="left_link_0.0">
    <visual>
      <geometry>
        <mesh filename="package://allegro_hand_description/meshes/link_0.0.STL"/>
      </geometry>
      <material name="black"/>
    </visual>
    <collision>
      <geometry>
        <box size="0.0196 0.0275 0.0164"/>
      </geometry>
      <origin rpy="0.0 0.0 0.0" xyz="0 0 0.0082"/>
    </collision>
    <inertial>
      <mass value="0.0119"/>
      <origin rpy="0 0 0" xyz="0.0 0.0 0.0"/>
      <inertia ixx="1.01666658333e-06" ixy="0.0" ixz="0.0" iyy="6.47677333333e-07" iyz="0.0" izz="1.01666658333e-06"/>
    </inertial>
  </link>
  <joint name="left_joint_0" type="revolute">
    <axis xyz="0 0 1"/>
    <limit effort="0" lower="-0.47" upper="0.47" velocity="0"/>
    <parent link="left_palm_link"/>
    <child link="left_link_0.0"/>
    <origin rpy="0.08726646255 0 0" xyz="0 -0.0435 -0.001542"/>
    <dynamics friction="10"/>
  </joint>
  <transmission name="tran1">
    <type>transmission_interface/SimpleTransmission</type>
    <joint name="left_joint_0">
      <hardwareInterface>EffortJointInterface</hardwareInterface>
    </joint>
    <actuator name="motor1">
      <hardwareInterface>EffortJointInterface</hardwareInterface>
      <mechanicalReduction>1</mechanicalReduction>
    </actuator>
  </transmission>
  <!-- [LINK 1, 5, 9] -->
  <link name="left_link_1.0">
    <visual>
      <geometry>
        <mesh filename="package://allegro_hand_description/meshes/link_1.0.STL"/>
      </geometry>
      <material name="black"/>
    </visual>
    <collision>
      <geometry>
        <box size="0.0196 0.0275 0.054"/>
      </geometry>
      <origin rpy="0.0 0.0 0.0" xyz="0 0 0.027"/>
    </collision>
    <inertial>
      <mass value="0.065"/>
      <origin rpy="0 0 0" xyz="0.0 0.0 0.0"/>
      <inertia ixx="7.95654166667e-05" ixy="1.7199e-05" ixz="8.75875e-06" iyy="2.47088833333e-05" iyz="2.413125e-05" izz="7.95654166667e-05"/>
    </inertial>
  </link>
  <joint name="left_joint_1" type="revolute">
    <limit effort="0" lower="-0.196" upper="1.61" velocity="0"/>
    <axis xyz="0 1 0"/>
    <parent link="left_link_0.0"/>
    <child link="left_link_1.0"/>
    <origin xyz="0 0 0.0164"/>
    <dynamics friction="5"/>
  </joint>
  <transmission name="tran1">
    <type>transmission_interface/SimpleTransmission</type>
    <joint name="left_joint_1">
      <hardwareInterface>EffortJointInterface</hardwareInterface>
    </joint>
    <actuator name="motor1">
      <hardwareInterface>EffortJointInterface</hardwareInterface>
      <mechanicalReduction>1</mechanicalReduction>
    </actuator>
  </transmission>
  <!-- [LINK 2, 6, 10]-->
  <link name="left_link_2.0">
    <visual>
      <geometry>
        <mesh filename="package://allegro_hand_description/meshes/link_2.0.STL"/>
      </geometry>
      <material name="black"/>
    </visual>
    <collision>
      <geometry>
        <box size="0.0196 0.0275 0.0384"/>
      </geometry>
      <origin rpy="0.0 0.0 0.0" xyz="0 0 0.0192"/>
    </collision>
    <inertial>
      <mass value="0.0355"/>
      <origin rpy="0 0 0" xyz="0.0 0.0 0.0"/>
      <inertia ixx="2.63979183333e-05" ixy="6.67968e-06" ixz="4.783625e-06" iyy="1.34948516667e-05" iyz="9.372e-06" izz="2.63979183333e-05"/>
    </inertial>
  </link>
  <joint name="left_joint_2" type="revolute">
    <axis xyz="0 1 0"/>
    <limit effort="0" lower="-0.174" upper="1.709" velocity="0"/>
    <parent link="left_link_1.0"/>
    <child link="left_link_2.0"/>
    <origin xyz="0 0 0.054"/>
    <dynamics friction="10"/>
  </joint>
  <transmission name="tran1">
    <type>transmission_interface/SimpleTransmission</type>
    <joint name="left_joint_2">
      <hardwareInterface>EffortJointInterface</hardwareInterface>
    </joint>
    <actuator name="motor1">
      <hardwareInterface>EffortJointInterface</hardwareInterface>
      <mechanicalReduction>1</mechanicalReduction>
    </actuator>
  </transmission>
  <!-- [LINK 3, 7, 11] -->
  <link name="left_link_3.0">
    <visual>
      <geometry>
        <mesh filename="package://allegro_hand_description/meshes/link_3.0.STL"/>
      </geometry>
      <material name="black"/>
    </visual>
    <collision>
      <geometry>
        <box size="0.0196 0.0275 0.0267"/>
      </geometry>
      <origin rpy="0.0 0.0 0.0" xyz="0 0 0.01335"/>
    </collision>
    <inertial>
      <mass value="0.0096"/>
      <origin rpy="0 0 0" xyz="0.0 0.0 0.0"/>
      <inertia ixx="4.701248e-06" ixy="1.255968e-06" ixz="1.2936e-06" iyy="3.649312e-06" iyz="1.7622e-06" izz="4.701248e-06"/>
    </inertial>
  </link>
  <joint name="left_joint_3" type="revolute">
    <axis xyz="0 1 0"/>
    <limit effort="0" lower="-0.227" upper="1.618" velocity="0"/>
    <parent link="left_link_2.0"/>
    <child link="left_link_3.0"/>
    <origin xyz="0 0 0.0384"/>
    <dynamics friction="12"/>
  </joint>
  <transmission name="tran1">
    <type>transmission_interface/SimpleTransmission</type>
    <joint name="left_joint_3">
      <hardwareInterface>EffortJointInterface</hardwareInterface>
    </joint>
    <actuator name="motor1">
      <hardwareInterface>EffortJointInterface</hardwareInterface>
      <mechanicalReduction>1</mechanicalReduction>
    </actuator>
  </transmission>
  <!-- [FINGER TIP] -->
  <link name="left_link_3.0_tip">
    <visual>
      <geometry>
        <mesh filename="package://allegro_hand_description/meshes/link_3.0_tip.STL"/>
      </geometry>
      <material name="white">
        <color rgba=".9 .9 .9 1"/>
      </material>
    </visual>
    <collision>
      <geometry>
        <sphere radius="0.012"/>
      </geometry>
    </collision>
    <inertial>
      <mass value="0.0168"/>
      <origin rpy="0 0 0" xyz="0.0 0.0 0.0"/>
      <inertia ixx="9.68e-07" ixy="0.0" ixz="0.0" iyy="9.68e-07" iyz="0.0" izz="9.68e-07"/>
    </inertial>
  </link>
  <joint name="left_joint_3_tip" type="fixed">
    <parent link="left_link_3.0"/>
    <child link="left_link_3.0_tip"/>
    <origin rpy="0.0 0.0 0.0" xyz="0 0 0.0267"/>
  </joint>
  <!-- THUMB -->
  <!--
<xacro:thumb_right
	finger_num=			"3" 
	offset_origin_x=	"-0.0182"	
	offset_origin_y=	"0.019333" 
	offset_origin_z=	"-0.045987"
	
	
	finger_angle_r=		"0"
	finger_angle_p=		"-${95*DEG2RAD}"	
	finger_angle_y=		"-${90*DEG2RAD}"
/>
-->
  <!--
	finger_angle_r=		"${90*DEG2RAD}"
	finger_angle_p=		"-${100*DEG2RAD}"	
	finger_angle_y=		"${0*DEG2RAD}"
	-->
  <!-- [LINK 12] -->
  <link name="left_link_12.0">
    <visual>
      <geometry>
        <!-- RIGHT -->
        <!-- <mesh filename="package://allegro_hand_description/meshes/link_12.0_right.STL" /> -->
        <!-- LEFT -->
        <mesh filename="package://allegro_hand_description/meshes/link_12.0_left.STL"/>
      </geometry>
      <material name="black">
        <color rgba=".2 .2 .2 1"/>
      </material>
      <origin rpy="3.1415926518 0 0" xyz="0 0 0"/>
    </visual>
    <collision>
      <geometry>
        <box size="0.0358 0.034 0.0455"/>
      </geometry>
      <!-- RIGHT -->
      <!-- <origin rpy="0.0 0.0 0.0" xyz="${-0.0358/2+0.0} ${.018/2} ${.029/2}"/> -->
      <!-- LEFT -->
      <origin rpy="0.0 0.0 0.0" xyz="-0.0179 -0.009 0.0145"/>
    </collision>
  </link>
  <joint name="left_joint_12" type="revolute">
    <axis xyz="+1 0 0"/>
    <limit effort="0" lower="0.263" upper="1.396" velocity="0"/>
    <parent link="left_palm_link"/>
    <child link="left_link_12.0"/>
    <origin rpy="0 -1.65806278845 1.5707963259" xyz="-0.0182 -0.019333 -0.045987"/>
    <dynamics friction="10"/>
  </joint>
  <transmission name="tran1">
    <type>transmission_interface/SimpleTransmission</type>
    <joint name="left_joint_12">
      <hardwareInterface>EffortJointInterface</hardwareInterface>
    </joint>
    <actuator name="motor1">
      <hardwareInterface>EffortJointInterface</hardwareInterface>
      <mechanicalReduction>1</mechanicalReduction>
    </actuator>
  </transmission>
  <!-- [LINK 13] -->
  <link name="left_link_13.0">
    <visual>
      <geometry>
        <mesh filename="package://allegro_hand_description/meshes/link_13.0.STL"/>
      </geometry>
      <material name="black">
        <color rgba=".2 .2 .2 1"/>
      </material>
    </visual>
    <collision>
      <geometry>
        <box size="0.0196 0.0275 0.0177"/>
      </geometry>
      <origin rpy="0.0 0.0 0.0" xyz="0 0 0.00885"/>
    </collision>
    <inertial>
      <mass value="0.0119"/>
      <origin rpy="0 0 0" xyz="0.0 0.0 0.0"/>
      <inertia ixx="4.24250866667e-06" ixy="1.032087e-06" ixz="1.603525e-06" iyy="4.52362633333e-06" iyz="1.44808125e-06" izz="4.24250866667e-06"/>
    </inertial>
  </link>
  <joint name="left_joint_13" type="revolute">
    <axis xyz="0 0 -1"/>
    <limit effort="0" lower="-0.105" upper="1.163" velocity="0"/>
    <parent link="left_link_12.0"/>
    <child link="left_link_13.0"/>
    <!-- RIGHT -->
    <!-- <origin xyz="-0.027 0.005 0.0399"/> -->
    <!-- LEFT -->
    <origin xyz="-0.027 -0.005 0.0399"/>
    <dynamics friction="5"/>
  </joint>
  <transmission name="tran1">
    <type>transmission_interface/SimpleTransmission</type>
    <joint name="left_joint_13">
      <hardwareInterface>EffortJointInterface</hardwareInterface>
    </joint>
    <actuator name="motor1">
      <hardwareInterface>EffortJointInterface</hardwareInterface>
      <mechanicalReduction>1</mechanicalReduction>
    </actuator>
  </transmission>
  <!-- [LINK 14] -->
  <link name="left_link_14.0">
    <visual>
      <geometry>
        <mesh filename="package://allegro_hand_description/meshes/link_14.0.STL"/>
      </geometry>
      <material name="black">
		  	</material>
    </visual>
    <collision>
      <geometry>
        <box size="0.0196 0.0275 0.0514"/>
      </geometry>
      <origin rpy="0.0 0.0 0.0" xyz="0 0 0.0257"/>
    </collision>
    <inertial>
      <mass value="0.038"/>
      <origin rpy="0 0 0" xyz="0.0 0.0 0.0"/>
      <inertia ixx="4.30439933333e-05" ixy="9.57068e-06" ixz="5.1205e-06" iyy="1.44451933333e-05" iyz="1.342825e-05" izz="4.30439933333e-05"/>
    </inertial>
  </link>
  <joint name="left_joint_14" type="revolute">
    <axis xyz="0 1 0"/>
    <limit effort="0" lower="-0.189" upper="1.644" velocity="0"/>
    <parent link="left_link_13.0"/>
    <child link="left_link_14.0"/>
    <origin xyz="0 0 0.0177"/>
    <dynamics friction="10"/>
  </joint>
  <transmission name="tran1">
    <type>transmission_interface/SimpleTransmission</type>
    <joint name="left_joint_14">
      <hardwareInterface>EffortJointInterface</hardwareInterface>
    </joint>
    <actuator name="motor1">
      <hardwareInterface>EffortJointInterface</hardwareInterface>
      <mechanicalReduction>1</mechanicalReduction>
    </actuator>
  </transmission>
  <!-- [LINK 15] -->
  <link name="left_link_15.0">
    <visual>
      <geometry>
        <mesh filename="package://allegro_hand_description/meshes/link_15.0.STL"/>
      </geometry>
      <material name="black">
    	</material>
    </visual>
    <collision>
      <geometry>
        <box size="0.0196 0.0275 0.0423"/>
      </geometry>
      <origin rpy="0.0 0.0 0.0" xyz="0 0 0.02115"/>
    </collision>
    <inertial>
      <mass value="0.0388"/>
      <origin rpy="0 0 0" xyz="0.0 0.0 0.0"/>
      <inertia ixx="3.29223173333e-05" ixy="8.042076e-06" ixz="5.2283e-06" iyy="1.47493026667e-5" iyz="1.1283525e-5" izz="3.29223173333e-05"/>
    </inertial>
  </link>
  <joint name="left_joint_15" type="revolute">
    <axis xyz="0 1 0"/>
    <limit effort="0" lower="-0.162" upper="1.719" velocity="0"/>
    <parent link="left_link_14.0"/>
    <child link="left_link_15.0"/>
    <origin xyz="0 0 0.0514"/>
    <dynamics friction="12"/>
  </joint>
  <transmission name="tran1">
    <type>transmission_interface/SimpleTransmission</type>
    <joint name="left_joint_15">
      <hardwareInterface>EffortJointInterface</hardwareInterface>
    </joint>
    <actuator name="motor1">
      <hardwareInterface>EffortJointInterface</hardwareInterface>
      <mechanicalReduction>1</mechanicalReduction>
    </actuator>
  </transmission>
  <!-- [FINGER TIP] -->
  <link name="left_link_15.0_tip">
    <visual>
      <geometry>
        <mesh filename="package://allegro_hand_description/meshes/link_15.0_tip.STL"/>
      </geometry>
      <material name="white">
        <color rgba=".9 .9 .9 1"/>
      </material>
    </visual>
    <collision>
      <geometry>
        <sphere radius="0.012"/>
      </geometry>
      <origin rpy="0.0 0.0 0.0" xyz="0 0 0"/>
    </collision>
    <inertial>
      <mass value="0.0168"/>
      <origin rpy="0 0 0" xyz="0.0 0.0 0.0"/>
      <inertia ixx="9.68e-07" ixy="0.0" ixz="0.0" iyy="9.68e-07" iyz="0.0" izz="9.68e-07"/>
    </inertial>
  </link>
  <joint name="left_joint_15_tip" type="fixed">
    <parent link="left_link_15.0"/>
    <child link="left_link_15.0_tip"/>
    <origin rpy="0.0 0.0 0.0" xyz="0 0 0.0423"/>
    <!--0.0267000000000005-->
  </joint>
  <!-- ============================================================================= -->
  <!-- ============================================================================= -->
  <!-- ============================================================================= -->
  <!-- THUMB MACRO -->
  <!-- END THUMB MACRO -->
  <!-- THREE FINGER MACRO -->
  <!-- [[END]] THREE FINGER MACRO -->
</robot>
